### Promise 对象
#### --- 事件循环 (前言）
> [js事件循环机制event-loop](https://segmentfault.com/a/1190000038928521)
---
#### --- Promise 的含义
> Promise 是异步编程的一种解决方案，比传统的解决方案——<ins>回调函数</ins>和<ins>事件</ins>——更合理和更强大。

> 所谓Promise，简单说就是一个容器，里面保存着某个未来才会结束的事件（通常是一个异步操作）的结果。

> Promise对象有以下两个特点。
> 1. 对象的状态不受外界影响。Promise对象代表一个异步操作，有三种状态：pending（进行中）、fulfilled（已成功）和rejected（已失败）。只有异步操作的结果，可以决定当前是哪一种状态，任何其他操作都无法改变这个状态。
> 2. 一旦状态改变，就不会再变，任何时候都可以得到这个结果。Promise对象的状态改变，只有两种可能：从pending变为fulfilled和从pending变为rejected。只要这两种情况发生，状态就凝固了，不会再变了，会一直保持这个结果，这时就称为 resolved（已定型）。

> Pro: 有了Promise对象，就可以将异步操作以同步操作的流程表达出来，避免了层层嵌套的回调函数。此外，Promise对象提供统一的接口，使得控制异步操作更加容易。

> Con: Promise也有一些缺点。首先，无法取消Promise，一旦新建它就会立即执行，无法中途取消。其次，如果不设置回调函数，Promise内部抛出的错误，不会反应到外部。第三，当处于pending状态时，无法得知目前进展到哪一个阶段（刚刚开始还是即将完成）。
---
#### --- 基本用法 (resolved统一只指fulfilled状态)
```javascript
const promise = new Promise(function(resolve, reject) {
  // ... some code

  if (/* 异步操作成功 */){
    resolve(value);
  } else {
    reject(error);
  }
});
```
> Promise构造函数接受一个函数作为参数，该函数的两个参数分别是resolve和reject。
> 1. resolve函数的作用是，将Promise对象的状态从“未完成”变为“成功”（即从 pending 变为 resolved），
在异步操作成功时调用，并将异步操作的结果，作为参数传递出去
> 2. reject函数的作用是，将Promise对象的状态从“未完成”变为“失败”（即从 pending 变为 rejected），
在异步操作失败时调用，并将异步操作报出的错误，作为参数传递出去

> Promise实例生成以后，可以用then方法分别指定resolved状态和rejected状态的回调函数。
```javascript
promise.then(function(value) {
  // success
}, function(error) {
  // failure
});
```
> 下面是一个Promise对象的简单例子。
```javascript
function timeout(ms) {
  return new Promise((resolve, reject) => {
    setTimeout(resolve, ms, 'done');
  });
}

timeout(100).then((value) => {
  console.log(value);
});
```
> 上面代码中，timeout方法返回一个Promise实例，表示一段时间以后才会发生的结果。过了指定的时间（ms参数）以后，Promise实例的状态变为resolved，就会触发then方法绑定的回调函数。

> Promise 新建后就会立即执行。
```javascript
let promise = new Promise(function(resolve, reject) {
  console.log('Promise');
  resolve();
});

promise.then(function() {
  console.log('resolved.');
});

console.log('Hi!');

// Promise
// Hi!
// resolved
```
> 上面代码中，Promise 新建后立即执行，所以首先输出的是Promise。然后，then方法指定的回调函数，将在当前脚本所有同步任务执行完才会执行，所以resolved最后输出。

> 下面是一个用Promise对象实现的 Ajax 操作的例子。
```javascript
const getJSON = function(url) {
  const promise = new Promise(function(resolve, reject){
    const handler = function() {
      if (this.readyState !== 4) {
        return;
      }
      if (this.status === 200) {
        resolve(this.response);
      } else {
        reject(new Error(this.statusText));
      }
    };
    const client = new XMLHttpRequest();
    client.open("GET", url);
    client.onreadystatechange = handler;
    client.responseType = "json";
    client.setRequestHeader("Accept", "application/json");
    client.send();

  });

  return promise;
};

getJSON("/posts.json").then(function(json) {
  console.log('Contents: ' + json);
}, function(error) {
  console.error('出错了', error);
});
```
> 上面代码中，getJSON是对 XMLHttpRequest 对象的封装，用于发出一个针对 JSON 数据的 HTTP 请求，并且返回一个Promise对象。需要注意的是，在getJSON内部，resolve函数和reject函数调用时，都带有参数。

> 如果调用resolve函数和reject函数时带有参数，那么它们的参数会被传递给回调函数。
> reject函数的参数通常是Error对象的实例，表示抛出的错误；resolve函数的参数除了正常的值以外，还可能是另一个 Promise 实例:
```javascript
const p1 = new Promise(function (resolve, reject) {
  setTimeout(() => reject(new Error('fail')), 3000)
})

const p2 = new Promise(function (resolve, reject) {
  setTimeout(() => resolve(p1), 1000)
})

p2
  .then(result => console.log(result))
  .catch(error => console.log(error))
// Error: fail
```
> 上面代码中，p1是一个 Promise，3 秒之后变为rejected。p2的状态在 1 秒之后改变，resolve方法返回的是p1。由于p2返回的是另一个 Promise，导致p2自己的状态无效了，由p1的状态决定p2的状态。所以，后面的then语句都变成针对后者（p1）。又过了 2 秒，p1变为rejected，导致触发catch方法指定的回调函数。

> p2的resolve方法将p1作为参数，即一个异步操作的结果是返回另一个异步操作。这时p1的状态就会传递给p2，也就是说，p1的状态决定了p2的状态。
> 1. 如果p1的状态是pending，那么p2的回调函数就会等待p1的状态改变。
> 2. 如果p1的状态已经是resolved或者rejected，那么p2的回调函数将会立刻执行。

> 注意，调用resolve或reject并不会终结 Promise 的参数函数的执行。
```javascript
new Promise((resolve, reject) => {
  resolve(1);
  console.log(2);
}).then(r => {
  console.log(r);
});
// 2
// 1
```
> 上面代码中，调用resolve(1)以后，后面的console.log(2)还是会执行，并且会首先打印出来。这是因为立即 resolved 的 Promise 是在本轮事件循环的末尾执行，总是晚于本轮循环的同步任务。

> 一般来说，调用resolve或reject以后，Promise 的使命就完成了，后继操作应该放到then方法里面，而不应该直接写在resolve或reject的后面。所以，最好在它们前面加上return语句，这样就不会有意外。
```javascript
new Promise((resolve, reject) => {
  return resolve(1);
  // 后面的语句不会执行
  console.log(2);
})
```
---
#### --- Promise.prototype.then()
> Promise 实例具有then方法，它的作用是为 Promise 实例添加状态改变时的回调函数。前面说过，then方法的第一个参数是resolved状态的回调函数，第二个参数是rejected状态的回调函数，它们都是可选的。

> then方法返回的是一个新的Promise实例（注意，不是原来那个Promise实例）。因此可以采用链式写法，即then方法后面再调用另一个then方法。
```javascript
getJSON("/posts.json").then(function(json) {
  return json.post;
}).then(function(post) {
  // ...
});
```
> 上面的代码使用then方法，依次指定了两个回调函数。第一个回调函数完成以后，会将返回结果作为参数，传入第二个回调函数。

> 采用链式的then，可以指定一组按照次序调用的回调函数。这时，前一个回调函数，有可能返回的还是一个Promise对象（即有异步操作），这时后一个回调函数，就会等待该Promise对象的状态发生变化，才会被调用。
```javascript
getJSON("/post/1.json").then(function(post) {
  return getJSON(post.commentURL);
}).then(function (comments) {
  console.log("resolved: ", comments);
}, function (err){
  console.log("rejected: ", err);
});
```
> 上面代码中，第一个then方法指定的回调函数，返回的是另一个Promise对象。这时，第二个then方法指定的回调函数，就会等待这个新的Promise对象状态发生变化。如果变为resolved，就调用第一个回调函数，如果状态变为rejected，就调用第二个回调函数。

> 如果采用箭头函数，上面的代码可以写得更简洁。
```javascript
getJSON("/post/1.json").then(
  post => getJSON(post.commentURL)
).then(
  comments => console.log("resolved: ", comments),
  err => console.log("rejected: ", err)
);
```
---
#### --- Promise.prototype.catch()
> Promise.prototype.catch()方法用于指定发生错误时的回调函数。
```javascript
getJSON('/posts.json').then(function(posts) {
  // ...
}).catch(function(error) {
  // 处理 getJSON 和 前一个回调函数运行时发生的错误
  console.log('发生错误！', error);
});
```
> 上面代码中，getJSON()方法返回一个 Promise 对象，如果该对象状态变为resolved，则会调用then()方法指定的回调函数；如果异步操作抛出错误，状态就会变为rejected，就会调用catch()方法指定的回调函数，处理这个错误。另外，then()方法指定的回调函数，如果运行中抛出错误，也会被catch()方法捕获。

```javascript
const promise = new Promise(function(resolve, reject) {
  throw new Error('test'); // or reject(new Error('test'));
});
promise.catch(function(error) {
  console.log(error);
});
// Error: test
```
> 上面代码中，promise抛出一个错误，就被catch()方法指定的回调函数捕获。

> 如果 Promise 状态已经变成resolved，再抛出错误是无效的。
```javascript
const promise = new Promise(function(resolve, reject) {
  resolve('ok');
  throw new Error('test');
});
promise
  .then(function(value) { console.log(value) })
  .catch(function(error) { console.log(error) });
// ok
```

> Promise 对象的错误具有“冒泡”性质，会一直向后传递，直到被捕获为止。也就是说，错误总是会被下一个catch语句捕获。
```javascript
getJSON('/post/1.json').then(function(post) {
  return getJSON(post.commentURL);
}).then(function(comments) {
  // some code
}).catch(function(error) {
  // 处理前面三个Promise产生的错误
});
```
> 上面代码中，一共有三个 Promise 对象：一个由getJSON()产生，两个由then()产生。它们之中任何一个抛出的错误，都会被最后一个catch()捕获。

> 一般来说，不要在then()方法里面定义 Reject 状态的回调函数（即then的第二个参数），总是使用catch方法。
```javascript
// bad
promise
  .then(function(data) {
    // success
  }, function(err) {
    // error
  });

// good
promise
  .then(function(data) { 
    // success
  })
  .catch(function(err) {
    // error
  });
```

> 跟传统的try/catch代码块不同的是，如果没有使用catch()方法指定错误处理的回调函数，Promise 对象抛出的错误不会传递到外层代码，即不会有任何反应。
```javascript
const someAsyncThing = function() {
  return new Promise(function(resolve, reject) {
    // 下面一行会报错，因为x没有声明
    resolve(x + 2);
  });
};

someAsyncThing().then(function() {
  console.log('everything is great');
});

setTimeout(() => { console.log(123) }, 2000);
// Uncaught (in promise) ReferenceError: x is not defined
// 123
```
> 上面代码中，someAsyncThing()函数产生的 Promise 对象，内部有语法错误。浏览器运行到这一行，会打印出错误提示ReferenceError: x is not defined，但是不会退出进程、终止脚本执行，2 秒之后还是会输出123。这就是说，Promise 内部的错误不会影响到 Promise 外部的代码，通俗的说法就是“Promise 会吃掉错误”。

> 一般总是建议，Promise 对象后面要跟catch()方法，这样可以处理 Promise 内部发生的错误。catch()方法返回的还是一个 Promise 对象，因此后面还可以接着调用then()方法。
```javascript
someAsyncThing().then(function() {
  return someOtherAsyncThing();
}).catch(function(error) {
  console.log('oh no', error);
  // 下面一行会报错，因为y没有声明
  y + 2;
}).catch(function(error) {
  console.log('carry on', error);
});
// oh no [ReferenceError: x is not defined]
// carry on [ReferenceError: y is not defined]
```
---
#### --- Promise.prototype.finally()
> finally()方法用于指定不管 Promise 对象最后状态如何，都会执行的操作。
```javascript
promise
.then(result => {···})
.catch(error => {···})
.finally(() => {···});
```
> 上面代码中，不管promise最后的状态，在执行完then或catch指定的回调函数以后，都会执行finally方法指定的回调函数。
```javascript
server.listen(port)
  .then(function () {
    // ...
  })
  .finally(server.stop);
```
> 服务器使用 Promise 处理请求，然后使用finally方法关掉服务器。

> finally方法的回调函数不接受任何参数，这意味着没有办法知道，前面的 Promise 状态到底是fulfilled还是rejected。这表明，finally方法里面的操作，应该是与状态无关的，不依赖于 Promise 的执行结果。
---
#### --- Promise.all()
> Promise.all()方法用于将多个 Promise 实例，包装成一个新的 Promise 实例。
```javascript
const p = Promise.all([p1, p2, p3]);
```
> p的状态由p1、p2、p3决定，分成两种情况。
> 1. 只有p1、p2、p3的状态都变成fulfilled，p的状态才会变成fulfilled，此时p1、p2、p3的返回值组成一个数组，传递给p的回调函数。
> 2. 只要p1、p2、p3之中有一个被rejected，p的状态就变成rejected，此时第一个被reject的实例的返回值，会传递给p的回调函数。
```javascript
// 生成一个Promise对象的数组
const promises = [2, 3, 5, 7, 11, 13].map(function (id) {
  return getJSON('/post/' + id + ".json");
});

Promise.all(promises).then(function (posts) {
  // ...
}).catch(function(reason){
  // ...
});
```
> 下面是另一个例子。
```javascript
const databasePromise = connectDatabase();

const booksPromise = databasePromise
  .then(findAllBooks);

const userPromise = databasePromise
  .then(getCurrentUser);

Promise.all([
  booksPromise,
  userPromise
])
.then(([books, user]) => pickTopRecommendations(books, user));
```
> 上面代码中，booksPromise和userPromise是两个异步操作，只有等到它们的结果都返回了，才会触发pickTopRecommendations这个回调函数。
---
#### --- Promise.race() 
> Promise.race()方法同样是将多个 Promise 实例，包装成一个新的 Promise 实例。
```javascript
const p = Promise.race([p1, p2, p3]);
```
> 上面代码中，只要p1、p2、p3之中有一个实例率先改变状态，p的状态就跟着改变。那个率先改变的 Promise 实例的返回值，就传递给p的回调函数。

> 下面是一个例子，如果指定时间内没有获得结果，就将 Promise 的状态变为reject，否则变为resolve。
```javascript
const p = Promise.race([
  fetch('/resource-that-may-take-a-while'),
  new Promise(function (resolve, reject) {
    setTimeout(() => reject(new Error('request timeout')), 5000)
  })
]);

p
.then(console.log)
.catch(console.error);
```
> 上面代码中，如果 5 秒之内fetch方法无法返回结果，变量p的状态就会变为rejected，从而触发catch方法指定的回调函数。
---
#### --- Promise.allSettled()
> 有时候，我们希望等到一组异步操作都结束了，不管每一个操作是成功还是失败，再进行下一步操作。

> Promise.all()方法只适合所有异步操作都成功的情况，如果有一个操作失败，就无法满足要求。
```javascript
const urls = [url_1, url_2, url_3];
const requests = urls.map(x => fetch(x));

try {
  await Promise.all(requests);
  console.log('所有请求都成功。');
} catch {
  console.log('至少一个请求失败，其他请求可能还没结束。');
}
```
> 上面示例中，Promise.all()可以确定所有请求都成功了，但是只要有一个请求失败，它就会报错，而不管另外的请求是否结束。

> Promise.allSettled()方法接受一个数组作为参数，数组的每个成员都是一个 Promise 对象，并返回一个新的 Promise 对象。只有等到参数数组的所有 Promise 对象都发生状态变更（不管是fulfilled还是rejected），返回的 Promise 对象才会发生状态变更。
```javascript
const promises = [
  fetch('/api-1'),
  fetch('/api-2'),
  fetch('/api-3'),
];

await Promise.allSettled(promises);
removeLoadingIndicator();
```
> 上面示例中，数组promises包含了三个请求，只有等到这三个请求都结束了（不管请求成功还是失败），removeLoadingIndicator()才会执行。
