### Generator 函数的语法
#### --- 基本概念
> Generator 函数是 ES6 提供的一种异步编程解决方案，语法行为与传统函数完全不同。

> Generator 函数有多种理解角度。
> 1. 语法上，首先可以把它理解成，<ins>Generator 函数是一个状态机，封装了多个内部状态</ins>。<ins>执行 Generator 函数会返回一个遍历器对象, 可以依次遍历 Generator 函数内部的每一个状态</ins>。
> 2. 形式上，Generator 函数是一个普通函数，但是有两个特征。<ins>一是，function关键字与函数名之间有一个星号</ins>；二是，<ins>函数体内部使用`yield`表达式，定义不同的内部状态</ins>。
```javascript
function* helloWorldGenerator() {
  yield 'hello';
  yield 'world';
  return 'ending';
}

var hw = helloWorldGenerator();
```
> 上面代码定义了一个 Generator 函数`helloWorldGenerator`，它内部有两个`yield`表达式（hello和world），即该函数有三个状态：hello，world 和 return 语句（结束执行）。

> - Generator 函数的调用方法与普通函数一样，也是在函数名后面加上一对圆括号。不同的是，<ins>调用 Generator 函数后，该函数并不执行，返回的也不是函数运行结果，而是一个指向内部状态的指针对象</ins>。
> - 通过调用遍历器对象的`next`方法，使得指针移向下一个状态。每次调用`next`方法，内部指针就从函数头部或上一次停下来的地方开始执行，直到遇到下一个`yield`表达式（或`return`语句）为止。
```javascript
hw.next()
// { value: 'hello', done: false }

hw.next()
// { value: 'world', done: false }

hw.next()
// { value: 'ending', done: true }

hw.next()
// { value: undefined, done: true }
```
> 总结一下，调用 Generator 函数，返回一个遍历器对象，代表 Generator 函数的内部指针。以后，每次调用遍历器对象的`next`方法，就会返回一个有着`value`和`done`两个属性的对象。`value`属性表示当前的内部状态的值，是`yield`表达式后面那个表达式的值；`done`属性是一个布尔值，表示是否遍历结束。
---
#### --- yield 表达式
> 由于 Generator 函数返回的遍历器对象，只有调用`next`方法才会遍历下一个内部状态，所以其实提供了一种可以暂停执行的函数。`yield`表达式就是暂停标志。

> 遍历器对象的`next`方法的运行逻辑如下。
> 1. 遇到`yield`表达式，就暂停执行后面的操作，并将紧跟在`yield`后面的那个表达式的值，作为返回的对象的`value`属性值。
> 2. 下一次调用`next`方法时，再继续往下执行，直到遇到下一个`yield`表达式。
> 3. 如果没有再遇到新的`yield`表达式，就一直运行到函数结束，直到`return`语句为止，并将`return`语句后面的表达式的值，作为返回的对象的`value`属性值。
> 4. 如果该函数没有`return`语句，则返回的对象的`value`属性值为`undefined`。
```javascript
function* gen() {
  yield  123 + 456;
}

var g = gen()
g.next() => {value: 579, done: false}
g.next() => {value: undefined, done: true}
```
> `yield`表达式与`return`语句既有相似之处，也有区别。相似之处在于，都能返回紧跟在语句后面的那个表达式的值。区别在于每次遇到`yield`，函数暂停执行，下一次再从该位置继续向后执行，而`return`语句不具备位置记忆的功能。一个函数里面，只能执行一次（或者说一个）`return`语句，但是可以执行多次（或者说多个）`yield`表达式。

> 需要注意，`yield`表达式只能用在 Generator 函数里面，用在其他地方都会报错。
```javascript
(function (){
  yield 1;
})()
// SyntaxError: Unexpected number
```
> 另外，`yield`表达式如果用在另一个表达式之中，必须放在圆括号里面。
```javascript
function* demo() {
  console.log('Hello' + yield); // SyntaxError
  console.log('Hello' + yield 123); // SyntaxError

  console.log('Hello' + (yield)); // OK
  console.log('Hello' + (yield 123)); // OK
}
```
> `yield`表达式用作函数参数或放在赋值表达式的右边，可以不加括号。
```javascript
function* demo() {
  foo(yield 'a', yield 'b'); // OK
  let input = yield; // OK
}
```
---
#### --- 与 Iterator 接口的关系
> 由于 Generator 函数就是遍历器生成函数，因此可以把 Generator 赋值给对象的`Symbol.iterator`属性，从而使得该对象具有 Iterator 接口。
```javascript
var myIterable = {};
myIterable[Symbol.iterator] = function* () {
  yield 1;
  yield 2;
  yield 3;
};

[...myIterable] // [1, 2, 3]
```
---
#### --- next 方法的参数
> `yield`表达式本身没有返回值，或者说总是返回`undefined`。`next`方法可以带一个参数，该参数就会被当作上一个`yield`表达式的返回值。
```javascript
function* f() {
  for(var i = 0; true; i++) {
    var reset = yield i;
    if(reset) { i = -1; }
  }
}

var g = f();

g.next() // { value: 0, done: false }
g.next() // { value: 1, done: false }
g.next(true) // { value: 0, done: false }
```
> 上面代码先定义了一个可以无限运行的 Generator 函数f，如果`next`方法没有参数，每次运行到`yield`表达式，变量`reset`的值总是`undefined`。当`next`方法带一个参数`true`时，变量`reset`就被重置为这个参数（即`true`），因此`i`会等于-1，下一轮循环就会从-1开始递增。

> 这个功能有很重要的语法意义。Generator 函数从暂停状态到恢复运行，它的上下文状态（context）是不变的。通过`next`方法的参数，就有办法在 Generator 函数开始运行之后，继续向函数体内部注入值。<ins>也就是说，可以在 Generator 函数运行的不同阶段，从外部向内部注入不同的值，从而调整函数行为</ins>。
```javascript
function* foo(x) {
  var y = 2 * (yield (x + 1));
  var z = yield (y / 3);
  return (x + y + z);
}

var a = foo(5);
a.next() // Object{value:6, done:false}
a.next() // Object{value:NaN, done:false}
a.next() // Object{value:NaN, done:true}

var b = foo(5);
b.next() // { value:6, done:false }
b.next(12) // { value:8, done:false }
b.next(13) // { value:42, done:true }
```
> 上面代码中，第二次运行`next`方法的时候不带参数，导致 `y` 的值等于`2 * undefined`（即`NaN`），除以 `3` 以后还是`NaN`，因此返回对象的`value`属性也等于`NaN`。第三次运行`next`方法的时候不带参数，所以`z`等于`undefined`，返回对象的`value`属性等于`5 + NaN + undefined`，即`NaN`。

> 如果向`next`方法提供参数，返回结果就完全不一样了。上面代码第一次调用`b`的`next`方法时，返回`x+1`的值`6`；第二次调用`next`方法，将上一次`yield`表达式的值`"yield (x + 1)"`设为`12`，因此`y`等于`24`，返回`y / 3`的值`8`；第三次调用`next`方法，将上一次`yield`表达式的值设为`13`，因此`z`等于`13`，这时`x`等于`5`，`y`等于`24`，所以`return`语句的值等于`42`。

> 注意，由于`next`方法的参数表示上一个`yield`表达式的返回值，所以在第一次使用`next`方法时，传递参数是无效的。

> 再看一个通过`next`方法的参数，向 Generator 函数内部输入值的例子。
```javascript
function* dataConsumer() {
  console.log('Started');
  console.log(`1. ${yield}`);
  console.log(`2. ${yield}`);
  return 'result';
}

let genObj = dataConsumer();
genObj.next();
// Started
genObj.next('a')
// 1. a
genObj.next('b')
// 2. b
```
---
#### --- for...of 循环 
> `for...of`循环可以自动遍历 Generator 函数运行时生成的Iterator对象，且此时不再需要调用`next`方法。
```javascript
function* foo() {
  yield 1;
  yield 2;
  yield 3;
  yield 4;
  yield 5;
  return 6;
}

for (let v of foo()) {
  console.log(v);
}
// 1 2 3 4 5
```
> 下面是一个利用 Generator 函数和`for...of`循环，实现斐波那契数列的例子。
```javascript
function* fibonacci() {
  let [prev, curr] = [0, 1];
  for (;;) {
    yield curr;
    [prev, curr] = [curr, prev + curr];
  }
}

for (let n of fibonacci()) {
  if (n > 1000) break;
  console.log(n);
}
```
---
#### --- Generator.prototype.throw()
> Generator 函数返回的遍历器对象，都有一个`throw`方法，可以在函数体外抛出错误，然后在 Generator 函数体内捕获。
```javascript
var g = function* () {
  try {
    yield;
  } catch (e) {
    console.log('内部捕获', e);
  }
};

var i = g();
i.next();

try {
  i.throw('a');
  i.throw('b');
} catch (e) {
  console.log('外部捕获', e);
}
// 内部捕获 a
// 外部捕获 b
```
> 上面代码中，遍历器对象`i`连续抛出两个错误。第一个错误被 Generator 函数体内的`catch`语句捕获。i第二次抛出错误，由于 Generator 函数内部的`catch`语句已经执行过了，不会再捕捉到这个错误了，所以这个错误就被抛出了 Generator 函数体，被函数体外的`catch`语句捕获。

> `throw`方法可以接受一个参数，该参数会被`catch`语句接收，建议抛出`Error`对象的实例。
```javascript
var g = function* () {
  try {
    yield;
  } catch (e) {
    console.log(e);
  }
};

var i = g();
i.next();
i.throw(new Error('出错了！'));
// Error: 出错了！(…)
```
> 注意，不要混淆遍历器对象的`throw`方法和全局的`throw`命令。上面代码的错误，是用遍历器对象`g`的`throw`方法抛出的，而不是用`throw`命令抛出的。后者只能被函数体外的`catch`语句捕获。
```javascript
try {
  throw new Error('a');
  throw new Error('b');
} catch (e) {
  console.log('外部捕获', e);
}
// 外部捕获 [Error: a]
```
> 上面代码之所以只捕获了`a`，是因为函数体外的`catch`语句块`"console.log('外部捕获', e);"`，捕获了抛出的`a`错误以后，就不会再继续`try`代码块里面剩余的语句了。

> 如果 Generator 函数内部没有部署`try...catch`代码块，那么`throw`方法抛出的错误，将被外部`try...catch`代码块捕获。
```javascript
var g = function* () {
  while (true) {
    yield;
    console.log('内部捕获', e);
  }
};

var i = g();
i.next();

try {
  i.throw('a');
  i.throw('b');
} catch (e) {
  console.log('外部捕获', e);
}
// 外部捕获 a
```

> 如果 Generator 函数内部和外部，都没有部署`try...catch`代码块，那么程序将报错，直接中断执行。

> <ins>`throw`方法抛出的错误要被内部捕获，前提是必须至少执行过一次next方法</ins>。
```javascript
function* gen() {
  try {
    yield 1;
  } catch (e) {
    console.log('内部捕获');
  }
}

var g = gen();
g.throw(1);
// Uncaught 1
```
> `throw`方法被捕获以后，会附带执行下一条`yield`表达式。也就是说，会附带执行一次`next`方法。
```javascript
var gen = function* gen(){
  try {
    yield console.log('a');
  } catch (e) {
    // ...
  }
  yield console.log('b');
  yield console.log('c');
}

var g = gen();
g.next() // a
g.throw() // b
g.next() // c
```
> 上面代码中，`g.throw`方法被捕获以后，自动执行了一次`next`方法，所以会打印`b`。另外，也可以看到，只要 Generator 函数内部部署了`try...catch`代码块，那么遍历器的`throw`方法抛出的错误，不影响下一次遍历。

> 另外，`throw`命令与`g.throw`方法是无关的，两者互不影响。
```javascript
var gen = function* gen(){
  yield console.log('hello');
  yield console.log('world');
}

var g = gen();
g.next(); // hello

try {
  throw new Error();
} catch (e) {
  g.next(); // world
}
```
---

